# 异常处理机制

《Java编程思想》中对“异常”的解释是：
> 阻止当前方法或作用域继续执行的问题

所以异常是导致程序失败的可能原因，Java异常处理就是要告诉开发人员，程序出现了不正常的情况，需要注意。

异常处理机制，目的就是将错误的地方和错误处理的地方分离，从而避免因为在有可能产生错误的代码中加入过多的错误检测，影响程序本身的执行逻辑。

在C语言中，通常都是通过函数返回值进行判断并采取响应措施的，给程序员带来了非常大的工作量，并且逻辑混乱。C++和Java都采取了异常处理机制。


## Checked还是Unchecked

## Java异常层次结构
下面这张图清晰地概括了Java异常的层次结构：

![Exception_hierarchy](http://ovn0i3kdg.bkt.clouddn.com/Exception_hierarchy.png?imageView/2/w/400/q/90)

首先`Throwable`是所有异常类的“顶级”父类（这种说法不是很正确啦，因为所有类的的顶级父类是Object，我这里指的是在异常领域内的意思，所以加了引号，不要在意细节~），这个类里面定义定义了很多底层的东西，比如异常消息message，异常原因cause，堆栈轨迹stackTrace及相应的调用方法等。

往下分出了两个子类`Error`和`Exception`。

其中`Error`属于严重错误，大多数错误与代码编写者执行的操作无关，而表示代码运行时 JVM（Java 虚拟机）出现的问题。例如，Java虚拟机运行错误（Virtual MachineError），当 JVM 不再有继续执行操作所需的内存资源时，将出现`OutOfMemoryError`。这些异常发生时，Java虚拟机（JVM）一般会选择线程终止。这些错误表示故障发生于虚拟机自身、或者发生在虚拟机试图执行应用时，如Java虚拟机运行错误（`Virtual MachineError`）、类定义错误（`NoClassDefFoundError`）等。这些错误是不可查的，因为它们在应用程序的控制和处理能力之 外，而且绝大多数是程序运行时不允许出现的状况。对于设计合理的应用程序来说，即使确实发生了错误，本质上也不应该试图去处理它所引起的异常状况。在 Java中，错误通过Error的子类描述。这类异常不需要捕捉。**按照Java惯例，我们是不应该是实现任何新的Error子类的！**



而`Exception`是合理的应用程序想要捕获的条件。

而`Exception`又分出了两个派别`Checked Exception`和`Unchecked Exception`，两者有什么区别呢？
  - `Checked Exception`: 受检查的异常，其必须被`try-catch`语句块所捕获，或者通过`throws`子句声明。之所以命名为`Checked`，是因为Java编译器和JVM都要进行检查，以确保这个规则得以遵守。假如子类可能产生A异常，那么在父类中也必须throws A异常。
  - `Unchecked Exception`：不受检查的异常，这类异常不能通过代码来试图解决，所以称为`Unchecked exception`。程序无需捕捉这类异常，“无需”的意思就是程序员可以分析代码决定是不是要进行捕获和处理。

上图中，`Exception`下的子类中，粉色的是`Checked Exception`，蓝色的是`Unchecked Exception`，可以看到后者都是`RuntimeException`的子类，`RuntimeException`名字起得的就很有意思是，表示JVM运行时候引发的错误。

对于上面三种类型的异常，我们应该使用哪种异常？《Effective Java》中给出的建议是：**对于可以恢复的条件使用被检查异常，对于程序错误使用运行时异常。**

> 如果以Checked和Unchecked来划分的话，Error也是Unchecked的，所以上图中Error也标注成了蓝色。

> **需要记住一些常见的异常是属于哪一类的!!!**


### Throwable类
看源码可以看到，`Throwable`非常重要，因为它定义了底层实现细节，下面列出的是该类的一些关键点：
* `message`：这个属性保存了关于异常类的说明，可以通过`String getMessage()`获得。另外还有一个方法`String getLocalizedMessage()`可以获得，用户可以重写`getLocalizedMessage`从而生成自定义的消息格式，如果没有重写，则与`getMessage`输出相同。要设置`message`必须通过构造函数。在`toString`方法中会调用这个`getMessage`得到这个信息说明。
* `cause`：因由。当我们在捕获到一个异常后想抛出另一个异常，并且希望把原始的异常信息保存下来，就可以调用构造器把原始的异常对象保存到新的`Throwable`的`cause`中，如`Throwable(String message, Throwable cause)`。或者构造新的异常对象时没有初始化`cause`，则可以调用`Throwable initCause(Throwable cause)`，这个方法最多只能调用一次，也就是说`cause`一旦初始化了就不能再设置。 可以把`cause`看成是链表元素中指向上一个元素的引用，所以最终将形成一条**异常链**。异常链的信息会在`printStackTrace()`中打印出来。

* `StackTrace`：轨迹栈。栈轨迹记录了程序从开始到异常抛出点所调用的方法。通过`StackTraceElement[] getStackTrace()`可以获得一个`StackTraceElement`的数组，每个`StackTraceElement`记录一个栈帧，0号元素表示栈顶，由栈的FILO规则可知0号元素表示最后调用的方法，而栈底则表示第一个调用的方法，一般就是main了。

  `Throwable`提供了一个打印栈轨迹的方法`void printStackTrace()`，输出到System.err,如要输出到其它地方，可调用`printStackTrace(PrintStream s)`或`void printStackTrace(PrintWriter s)`。

  重抛异常时，异常对象的所有信息保持不变，所以`printStackTrace()`打印的将是原来异常抛出点的调用栈信息，而非重新抛出点的信息。要想更新这个信息，可以调用`Throwable fillInStackTrace()`，该函数将产生一个新的`Throwable`对象，它是通过把当前的调用栈信息填入原来那个异常对象而建立的。调用`fillInStackTrace()`的那一行成了异常的新发生地。不过`fillInStackTrace()`要生效必须保证`StackTrace`是可写的，这个可通过调用构造器`Throwable(String message, Throwable cause, boolean enableSuppression, boolean writableStackTrace)`实现。

* `SuppressedException`：被屏蔽的异常。保存被屏蔽的异常，可通过`Throwable[] getSuppressed()`获得。添加的话用`addSuppressed(Throwable exception)`，这个函数一般是在`try-with-resources`语句中由自动调用的。`try-with-resources`和`suppressedExceptions`都是JDK1.7的新特性，会在后面`try-with-resources`的学习中讲到。


### throw和throws
异常处理中除了try-catch-finally之外还有两个关键字，`throw`和`throws`，`throw`用来抛出异常，`throws`用在方法签名中，用来声明该方法可能抛出的异常。Java允许在catch块中重新抛出异常，交给调用者。
下面是一个很好的例子：
```java
public class Junk {
    public static void main(String args[]) {
          try {
                    a();
              } catch(HighLevelException e) {
                  e.printStackTrace();
              }
          }
         static void a() throws HighLevelException {
            try {
                b();
            } catch(MidLevelException e) {
                 throw new HighLevelException(e);
             }
         }
         static void b() throws MidLevelException {
             c();
         }
         static void c() throws MidLevelException {
             try {
                 d();
             } catch(LowLevelException e) {
                throw new MidLevelException(e);
             }
         }
         static void d() throws LowLevelException {
            e();
         }
         static void e() throws LowLevelException {
             throw new LowLevelException();
         }
     }

     class HighLevelException extends Exception {
         HighLevelException(Throwable cause) { super(cause); }
     }

     class MidLevelException extends Exception {
         MidLevelException(Throwable cause)  { super(cause); }
     }

     class LowLevelException extends Exception {
     }
 }
```
## try-catch-finally
前面说到开发者可以在程序中捕获异常，怎么捕获？通常用到的就是`try-catch-finally`。一般的写法如下：
```Java
      try {
           //代码区域
       }catch (Exception e){
           //异常处理区域
       }finally {
           //资源清理区域
       }
```
* `try`：用于监听。将要被监听的代码(可能抛出异常的代码)放在try语句块之内，当try语句块内发生异常时，异常就被抛出。
* `catch`：用于捕获异常。catch用来捕获try语句块中发生的异常。可以有很多个。
* `finally`：**finally语句块总是会被执行，不管有没有抛出异常，不管异常有没有被捕获**。它主要用于回收在try块里打开的物力资源(如数据库连接、网络连接和磁盘文件)。只有finally块，执行完成之后，才会回来执行try或者catch块中的return或者throw语句，如果finally中使用了return或者throw等终止方法的语句，则就不会跳回执行，直接停止。

针对`try-catch-finally`语句，需要注意一下几点：
* catch和finally至少得出现一个。如果catch出现了，必须紧跟着try。即try-catch-finally可能出现的组合形式有：`try-catch`、`try-catch-finally`、`try-finally`，不能存在`try-finall-catch`这种形式。
* catch可以有很多块，但是要注意异常匹配的顺序，先子类后父类，为什么这样呢？因为异常匹配的过程是一旦比配成功后面的就不执行了，这个switch的case是不一样的。
* "finally语句块总是会被执行，不管有没有抛出异常，不管异常有没有被捕获"，这句话成立有个前提，就是在程序进入try语句块之前没有出现程序退出以及try和catch块执行的过程中没有发成程序的意外退出，比如`System.exit(0)`，如果是这个样的话，那整个程序就退出了，finally块不会再执行了。

> 除了下列情况，总将执行 finally 做为结束： JVM 过早终止（调用 System.exit(int)）；在 finally 块中抛出一个未处理的异常；计算机断电、失火、或遭遇病毒攻击

* 关于try块中return语句是笔试中经常遇到的问题，关于return语句有这样的结论：
  - return语句不是函数的最终出口，如果有finally语句，这在return之后还会执行finally(return的值会存放在栈里面，等待finally执行止呕再返回)
  - 如果return出现在finally中，那么它会覆盖掉之前出现过的语句，并且执行后将执行权立即返回给调用者。
下面是一个典型的考察return的例子：
```Java
public class ExceptionTest {
    public static void main(String[] args) {
        System.out.println("=============NoException==================");
        System.out.println(NoException());
        System.out.println("===============================");
    }
    public static int NoException(){
        int i=10;
        try{
            System.out.println("i in try block is："+i); //10
            i = i/0;
            return --i;
        }
        catch(Exception e){
            System.out.println("i in catch - form try block is："+i); //10
            --i; // 9
            System.out.println("i in catch block is："+i);//9
            return --i; //8
        }
        finally{
            System.out.println("i in finally - from try or catch block is--"+i);//8
            --i; //7
            System.out.println("i in finally block is--"+i); //7
            return --i; //6
        }
    }
}
```
程序执行结果是：
```Java
=============NoException==================
i in try block is：10
i in catch - form try block is：10
i in catch block is：9
i in finally - from try or catch block is--8
i in finally block is--7
6
===============================
```
程序执行的过程如下：在try块中首先输出了i的值，是10，然后执行除法，这时候发生了`RuntimeException`，具体的是`MathException`，因为除数为0，这时候直接被catch捕捉到了异常（也就是说try块中的return根本就没有执行），然后输出此时的i值，还是10，之后自减为9，输出9，接着执行return语句，首先是自减为8，发现有finally块，就将这个值保存在栈中。在fianlly块中先打印当前i值，为8，然后自减为7，打印出7，再执行return，执行自减，变成6，上面说过，finally中如果return语句就会覆盖以前所有的return语句。所以返回的i的值是fianlly块中的执行结果6。

    这个题如果将所有的前置自减改成后置自减，那会是什么结果呢？同样做了实验，结果如下：
  ```Java
    =============NoException==================
    i in try block is：10
    i in catch - form try block is：10
    i in catch block is：9
    i in finally - from try or catch block is--8
    i in finally block is--7
    7
    ===============================
    ```
  各块的执行语句顺序没有什么变化，主要还是`return i--`这句话，先执行的是return，即原始值，然后在执行自减的。

    如果这道题去掉了finally块中的return语句，那么最终返回的将是catch块中的return中的值8。
> try-catch-finally 三者的执行顺序的深入分析可以参见 http://www.cnblogs.com/aigongsi/archive/2012/04/19/2457735.html

* try-catch-finally语句可以嵌套。
* fianlly块常用来清理资源。写法有很多用，例如一个文件读取文件的例子，这样的例子在JDBC的操作中也十分常见：
```Java
public void readFile(String file) {
    BufferedReader reader = null;
    try {
        reader = new BufferedReader(new InputStreamReader(
                new FileInputStream(file)));
        // do some other work
    } catch (FileNotFoundException e) {
        e.printStackTrace();
    } finally {
      reader.close();
    }
}
```
或者
```Java
public void readFile() {
    BufferedReader reader = null;
    try {
        reader = new BufferedReader(new InputStreamReader(
                new FileInputStream("file")));
        // do some other work

        //close reader
        reader.close();
    } catch (FileNotFoundException e) {
        e.printStackTrace();
    } catch (IOException e) {
        e.printStackTrace();
    }
}
```
注意两个方法的区别，前者考虑到由于finally子块一定被执行，所以将资源释放放到finally子块中。后者考虑到需要及早关闭资源，但是后者有一个问题在于reader.close()可能也会抛出异常，这样的话程序会在异常的地方跳出，不会执行后面的代码，此时我们可以用try-finally块来嵌套改造：
```Java
public void readFile() {
    BufferedReader reader = null;
    try {
        try {
            reader = new BufferedReader(new InputStreamReader(
                    new FileInputStream("file")));
            // do some other work

            // close reader
        } finally {
            reader.close();
        }
    } catch (FileNotFoundException e) {
        e.printStackTrace();
    } catch (IOException e) {
        e.printStackTrace();
    }
}
```
当然对于前者的写法，也可以采取下面的这种改造方法：
```Java
public void readFile(String file) {
    BufferedReader reader = null;
    try {
        reader = new BufferedReader(new InputStreamReader(
                new FileInputStream(file)));
        // do some other work
    } catch (FileNotFoundException e) {
        e.printStackTrace();
    } finally {
        try {
            reader.close();
        } catch (IOException e) {
            e.printStackTrace();
        }
    }
}
```
这两种写法，在网上看到的http://www.cnblogs.com/focusj/archive/2011/12/26/2301524.html 偏向于在try块中关闭。


* 将try块写的简短，不要什么东西都往里面扔，尽量分析出哪几行程序可能出现异常，只是对可能出现异常代码进行try。尽量为每一个异常写一个try-catch，避免异常丢失。


## try-with-resources
前面说到资源作为对象，必须在程序程序结束之后关闭，一般的做法就是放到finally块中进行手动关闭。JDK1.7之前我们都是这样做的，1.7及之后版本我们就可以使用try-with-resources语句，必须要再手动关闭资源。

try-with-resources语句确保在语句的最后每个资源都被关闭，任何实现了`java.lang.AutoCloseable`和`java.io.Closeable`的对象都可以使用try-with-resources来实现异常处理和关闭资源。用法如下：
```java
private static void customBufferStreamCopy(File source, File target) {
    try (InputStream fis = new FileInputStream(source);
        OutputStream fos = new FileOutputStream(target)){
        byte[] buf = new byte[8192];
        int i;
        while ((i = fis.read(buf)) != -1) {
            fos.write(buf, 0, i);
        }
    }
    catch (Exception e) {
        e.printStackTrace();
    }
}
```
注意看语法有什么不同了？之前的try是一块，现在try语句多了一个括号，而括号中就是一个资源对象。

> 在try后面加上括号，再初始化对象的语法叫做try-with-resources。这是Java的一颗语法糖。比如:
> ```java
>  try (BufferedReader br = new BufferedReader(new FileReader(path))) {  
>        return br.readLine();  
>    }
> ```
> 就相当于：

> ```java
>   BufferedReader br = new BufferedReader(new FileReader(path));  
>    try {  
>        return br.readLine();  
>    } finally {  
>        if (br != null) br.close();  
>   }  
>```

在使用try-with-resources语句的时候，异常可能会发生在try语句中，也可能发生在释放资源（即调用close方法）时。

如果异常发生在try语句中，则异常正常抛出，而资源也正常释放；如果try和释放过程都出现了异常，那么最终抛出的异常是try语句中的异常，在释放资源的过程中发生的异常被称为"被抑制的异常"，即`SuppressedException`，通过`Throwable.addSuppressed`方法被添加进去。

> try-with-resources怎么实现的呢?可以参考http://blog.csdn.net/hengyunabc/article/details/18459463

try-with-resources语句做出了很多的改进：
* 声明多个资源。例如：
```java
public class AboveJDK7_2 {  

    public static void writeToFileZipFileContents(String zipFileName,String outputFileName) throws java.io.IOException {  

        java.nio.charset.Charset charset = java.nio.charset.Charset.forName("US-ASCII");  

        java.nio.file.Path outputFilePath = java.nio.file.Paths.get(outputFileName);  

        //打开zip文件，创建输出流  
        try (  
                java.util.zip.ZipFile zf = new java.util.zip.ZipFile(zipFileName);  

                java.io.BufferedWriter writer = java.nio.file.Files.newBufferedWriter(outputFilePath, charset)  
            )   

            {//遍历文件写入txt  
                for (java.util.Enumeration entries = zf.entries(); entries.hasMoreElements();) {  

                        String newLine = System.getProperty("line.separator");  

                        String zipEntryName = ((java.util.zip.ZipEntry) entries.nextElement()).getName() + newLine;  
                        writer.write(zipEntryName, 0, zipEntryName.length());  
                        }  
            }  
      }  
}
```
这是一个在一个ZIP文件中检索文件名并将检索后的文件存入一个txt文件中的例子，这个例子无论是正常执行还是有异常抛出，zf和write都会执行cloase()方法，不过需要注意的是JVM里调用的顺序和声明的顺序相反，即调用的顺序是
```java
  writer.close();
  zf.close();
```
在使用的时候要注意资源关闭的顺序。

* catch多种异常。例如在1.7之前可能会有如下的try-catch块：
```java
      try{  
      //逻辑代码  
      }catch (IOException ex) {  
           logger.log(ex);  
           throw new SpecialException();  
      catch (SQLException ex) {  
           logger.log(ex);  
           throw new SpecialException();  
      }
```
两个不同的异常但是处理过程是一样的，写的很难看，在1.7之后可以采取这样的写法：
```java
      try{  
      //逻辑代码  
      }catch (IOException | SQLException ex) {  
           logger.log(ex);  
           throw new SpecialException();  
      }
```
其中ex是隐式的final，不可以在catch块中改变ex。

* catch多种异常后抛出新异常。例如在1.7之前，在方法声明中抛出的异常如果在方法体内没有抛出是不允许的。例如：

  ```java
  static class FirstException extends Exception {   

  }  

  static class SecondException extends Exception {  

  }  

  public void rethrowException(String exceptionName) throws Exception {  

    try {  

      if (exceptionName.equals("First")) {  
          //如果异常名称为"First"，则抛出异常一  
        throw new FirstException();  

      } else {  
          //否则的话，则抛出异常二  
        throw new SecondException();  

      }  

    } catch (Exception e) {  

      throw e;  
    }  
  }
  ```
1.7 之后就可以用这样的办法了：
  ```java
  static class FirstException extends Exception {   

  }  

  static class SecondException extends Exception {  

  }  

  public void rethrowException(String exceptionName) throws Exception, FirstException, SecondException {  
      try {  
        // 逻辑代码  
      }catch (Exception e) {  

        throw e;  
      }  
  }
  ```

之前说到能被try语句管理的资源需要实现两个接口，否则会有编译错误。当释放资源的时候，close方法被自动调用。Java类库中已有不少接口或类继承或实现了这个接口，使得它们可以用在try语句中。在这些已有的常见接口或类中，最常用的就是与I/O操作和数据库相关的接口。与I/O相关的`java.io.Closeable`继承了`AutoCloseable`，而与数据库相关的`java.sql.Connection`、`java.sql.ResultSet`和`java.sql.Statement`也继承了该接口。如果希望自己开发的类也能利用try语句的自动化资源管理，只需要实现`AutoCloseable`接口即可。

## multi-catch
multi-catch是1.7的新特性，就是说之前我们定义了很多catch块中的异常可以合起来写了，比如在1.7之前
```java
import java.io.*;

public class Hello {
    public static void main(String[] args) {
       try {
           throw new IOException("我错了");
       } catch (IOException e) {
           e.printStackTrace();
       } catch (Exception e) {
           e.printStackTrace();
       }
    }
}
```
先子类后父类，在1.7之后可以使用multi-catch语法：
```java
import java.io.*;

public class Hello {
    public static void main(String[] args) {
       try {
           throw new IOException("我错了");
       } catch (IOException | Exception e) {
           e.printStackTrace();
       }
    }
}
```
但是这在`IOException | Exception e`处出现编译错误，原因是`multi-catch`语法中的异常不能相交，即不能有父子关系，如果是`IOException | ClassNotFoundException`这种的就可以编译通过。



参考
* [Throwable、Error、Exception、RuntimeException 区别 联系](http://blog.csdn.net/liuj2511981/article/details/8524418)
* [异常处理 - Checked还是Unchecked](http://blog.csdn.net/sweetsoft/article/details/569498)
* [java中关于try、catch、finally中的细节分析](http://www.cnblogs.com/aigongsi/archive/2012/04/19/2457735.html)
* [有效处理Java异常三原则](http://www.importnew.com/1701.html)
* [关于Java中try-catch-finally-return的执行顺序](http://qing0991.blog.51cto.com/1640542/1387200)
* [Java7里try-with-resources分析](http://blog.csdn.net/hengyunabc/article/details/18459463)
* [JDK1.7中的multi-catch的变化](http://blog.csdn.net/fjh658/article/details/6437024)
